<?xml version="1.0" encoding="utf-8"?>
<!-- =================================================================================== -->
<!--   Copyright 2023 ANYbotics, https://www.anybotics.com                               -->
<!-- =================================================================================== -->
<!-- This file contains the description of the ANYmal robot. -->
<robot name="anymal">
  <link
    name="base">
    <inertial>
      <origin
        xyz="0.021112 0 -0.005366"
        rpy="0 0 0" />
      <mass
        value="6.921" />
      <inertia
        ixx="0.02448"
        ixy="0.00012166"
        ixz="0.0014849"
        iyy="0.098077"
        iyz="-3.12E-05"
        izz="0.107" />
    </inertial>
    <visual>
      <origin
        xyz="0 0 0"
        rpy="0 0 0" />
      <geometry>
        <mesh
          filename="package://ocs2_robotic_assets/resources/go2/dae/base.dae" />
      </geometry>
      <material
        name="">
        <color
          rgba="1 1 1 1" />
      </material>
    </visual>
    <collision>
      <origin rpy="0 0 0" xyz="0 0 0" />
      <geometry>
        <box size="0.3762 0.0935 0.114" />
      </geometry>
    </collision>
  </link>
  
  <!-- FRONT DEPTH CAMERA -->
  <joint name="base_face_front" type="fixed">
    <parent link="base"/>
    <child link="face_front"/>
    <origin rpy="0 0.0 -0.0" xyz="0.2 0 0.0205"/> <!-- xyz="0.4087 0 0.0205" -->
  </joint>
  <link name="face_front">
    <inertial>
      <origin rpy="0 0 0" xyz="-0.0362 0.00223 -0.02808"/>
      <mass value="0.48634"/>
      <inertia ixx="0.00077413444" ixy="1.55433e-06" ixz="6.243539e-05" iyy="0.00076586537" iyz="4.61106e-06" izz="0.00055588292"/>
    </inertial>
  </link>
  <joint name="face_front_to_depth_camera_front_lower_camera" type="fixed">
    <parent link="face_front"/>
    <child link="depth_camera_front_lower_camera"/>
    <origin rpy="0.0 1.0471975511965976 0" xyz="-0.04028 -0.025 -0.08051"/>
  </joint>
  <link name="depth_camera_front_lower_camera">
    <inertial>
      <origin rpy="0 0 0" xyz="-0.00362 -0.01787 -0.00011"/>
      <mass value="0.06355"/>
      <inertia ixx="6.841545e-05" ixy="1.46667e-06" ixz="4.115e-08" iyy="5.2817e-06" iyz="8.039e-08" izz="6.669787e-05"/>
    </inertial>
  </link>
  <joint name="depth_camera_front_lower_camera_to_camera_parent" type="fixed">
    <parent link="depth_camera_front_lower_camera"/>
    <child link="depth_camera_front_lower_camera_parent"/>
    <origin rpy="3.141592653589793 0.0 0.0" xyz="0.0 0.0 0.0"/>
  </joint>
  <link name="depth_camera_front_lower_camera_parent"/>
  <joint name="depth_camera_front_lower_camera_parent_to_depth_frame" type="fixed">
    <parent link="depth_camera_front_lower_camera_parent"/>
    <child link="depth_camera_front_lower_depth_frame"/>
    <origin rpy="0.0 0.0 0.0" xyz="0.0 0.0 0.0"/>
  </joint>
  <link name="depth_camera_front_lower_depth_frame"/>
  <joint name="depth_camera_front_lower_camera_depth_to_depth_optical_frame" type="fixed">
    <parent link="depth_camera_front_lower_depth_frame"/>
    <child link="depth_camera_front_lower_depth_optical_frame"/>
    <origin rpy="-1.5707963267948966 0.0 -1.5707963267948966" xyz="0.0 0.0 0.0"/>
  </joint>
  <link name="depth_camera_front_lower_depth_optical_frame"/>
  <joint name="face_front_to_depth_camera_front_upper_camera" type="fixed">
    <parent link="face_front"/>
    <child link="depth_camera_front_upper_camera"/>
    <origin rpy="0.0 0.2617993877991494 0" xyz="-0.00993 -0.025 -0.04096"/>
  </joint>
  <link name="depth_camera_front_upper_camera">
    <inertial>
      <origin rpy="0 0 0" xyz="-0.00362 -0.01787 -0.00011"/>
      <mass value="0.06355"/>
      <inertia ixx="6.841545e-05" ixy="1.46667e-06" ixz="4.115e-08" iyy="5.2817e-06" iyz="8.039e-08" izz="6.669787e-05"/>
    </inertial>
  </link>
  <joint name="depth_camera_front_upper_camera_to_camera_parent" type="fixed">
    <parent link="depth_camera_front_upper_camera"/>
    <child link="depth_camera_front_upper_camera_parent"/>
    <origin rpy="3.141592653589793 0.0 0.0" xyz="0.0 0.0 0.0"/>
  </joint>
  <link name="depth_camera_front_upper_camera_parent"/>
  <joint name="depth_camera_front_upper_camera_parent_to_depth_frame" type="fixed">
    <parent link="depth_camera_front_upper_camera_parent"/>
    <child link="depth_camera_front_upper_depth_frame"/>
    <origin rpy="0.0 0.0 0.0" xyz="0.0 0.0 0.0"/>
  </joint>
  <link name="depth_camera_front_upper_depth_frame"/>
  <joint name="depth_camera_front_upper_camera_depth_to_depth_optical_frame" type="fixed">
    <parent link="depth_camera_front_upper_depth_frame"/>
    <child link="depth_camera_front_upper_depth_optical_frame"/>
    <origin rpy="-1.5707963267948966 0.0 -1.5707963267948966" xyz="0.0 0.0 0.0"/>
  </joint>
  <link name="depth_camera_front_upper_depth_optical_frame"/>
  <joint name="face_front_to_wide_angle_camera_front_camera" type="fixed">
    <parent link="face_front"/>
    <child link="wide_angle_camera_front_camera"/>
    <origin rpy="0 0 0" xyz="0.0 0.0 0.0"/>
  </joint>
  <link name="wide_angle_camera_front_camera"/>
  <joint name="wide_angle_camera_front_camera_to_camera_parent" type="fixed">
    <parent link="wide_angle_camera_front_camera"/>
    <child link="wide_angle_camera_front_camera_parent"/>
    <origin rpy="-1.5707963267948966 0.0 -1.5707963267948966" xyz="-0.00421 0.0 0.0"/>
  </joint>
  <link name="wide_angle_camera_front_camera_parent"/>
  
  <!-- FRONT LEFT LEG -->
  <joint name="LF_HAA" type="revolute">
    <parent link="base" />
    <child link="LF_HIP" />
    <origin
      xyz="0.1934 0.0465 0"
      rpy="0 0 0" />
    <axis xyz="1 0 0" />
    <limit
      lower="-1.0472"
      upper="1.0472"
      effort="23.7"
      velocity="30.1" />
  </joint>
  <link name="LF_HIP">
    <inertial>
      <origin xyz="-0.0054 0.00194 -0.000105" rpy="0 0 0" />
      <mass
        value="0.678" />
      <inertia
        ixx="0.00048"
        ixy="-3.01E-06"
        ixz="1.11E-06"
        iyy="0.000884"
        iyz="-1.42E-06"
        izz="0.000596" />
    </inertial>
    <visual>
      <origin xyz="0 0 0" rpy="0 0 0" />
      <geometry>
        <mesh
          filename="package://ocs2_robotic_assets/resources/go2/dae/hip.dae" />
      </geometry>
      <material
        name="">
        <color
          rgba="1 1 1 1" />
      </material>
    </visual>
    <collision>
      <origin rpy="1.5707963267948966 0 0" xyz="0 0.08 0" />
      <geometry>
        <cylinder length="0.04" radius="0.046" />
      </geometry>
    </collision>
  </link>
  <joint name="LF_HFE" type="revolute">
    <parent
      link="LF_HIP" />
    <child
      link="LF_THIGH" />
    <origin
      xyz="0 0.0955 0"
      rpy="0 0 0" />
    <axis
      xyz="0 1 0" />
    <limit
      lower="-1.5708"
      upper="3.4907"
      effort="23.7"
      velocity="30.1" />
  </joint>
  <link name="LF_THIGH">
    <inertial>
      <origin
        xyz="-0.00374 -0.0223 -0.0327"
        rpy="0 0 0" />
      <mass
        value="1.152" />
      <inertia
        ixx="0.00584"
        ixy="8.72E-05"
        ixz="-0.000289"
        iyy="0.0058"
        iyz="0.000808"
        izz="0.00103" />
    </inertial>
    <visual>
      <origin
        xyz="0 0 0"
        rpy="0 0 0" />
      <geometry>
        <mesh
          filename="package://ocs2_robotic_assets/resources/go2/dae/thigh.dae" />
      </geometry>
      <material
        name="">
        <color
          rgba="1 1 1 1" />
      </material>
    </visual>
    <collision>
      <origin rpy="0 1.5707963267948966 0" xyz="0 0 -0.1065" />
      <geometry>
        <box size="0.213 0.0245 0.034" />
      </geometry>
    </collision>
  </link>  
  <joint name="LF_KFE" type="revolute">
    <origin
      xyz="0 0 -0.213"
      rpy="0 0 0" />
    <parent
      link="LF_THIGH" />
    <child
      link="LF_SHANK" />
    <axis
      xyz="0 1 0" />
    <limit
      lower="-2.7227"
      upper="-0.83776"
      effort="45.43"
      velocity="15.70" />
  </joint>
  <link name="LF_SHANK">
    <inertial>
      <origin
        xyz="0.00548 -0.000975 -0.115"
        rpy="0 0 0" />
      <mass
        value="0.154" />
      <inertia
        ixx="0.00108"
        ixy="3.4E-07"
        ixz="1.72E-05"
        iyy="0.0011"
        iyz="8.28E-06"
        izz="3.29E-05" />
    </inertial>
    <visual>
      <origin
        xyz="0 0 0"
        rpy="0 0 0" />
      <geometry>
        <mesh
          filename="package://ocs2_robotic_assets/resources/go2/dae/calf.dae" />
      </geometry>
      <material
        name="">
        <color
          rgba="1 1 1 1" />
      </material>
    </visual>
    <collision>
      <origin rpy="0 -0.21 0" xyz="0.008 0 -0.06" />
      <geometry>
        <cylinder length="0.12" radius="0.012" />
      </geometry>
    </collision>
  </link>  
  <link
    name="LF_calflower">
    <collision>
      <origin rpy="0 0 0" xyz="0 0 0" />
      <geometry>
        <cylinder length="0.065" radius="0.011" />
      </geometry>
    </collision>
  </link>
  <joint
    name="LF_calflower_joint"
    type="fixed">
    <origin
      xyz="0.020 0 -0.148"
      rpy="0 0.05 0" />
    <parent
      link="LF_SHANK" />
    <child
      link="LF_calflower" />
    <axis
      xyz="0 0 0" />
  </joint>
  <link
    name="LF_calflower1">
    <collision>
      <origin rpy="0 0 0" xyz="0 0 0" />
      <geometry>
        <cylinder length="0.03" radius="0.0155" />
      </geometry>
    </collision>
  </link>
  <joint
    name="LF_calflower1_joint"
    type="fixed">
    <origin
      xyz="-0.01 0 -0.04"
      rpy="0 0.48 0" />
    <parent
      link="LF_calflower" />
    <child
      link="LF_calflower1" />
    <axis
      xyz="0 0 0" />
  </joint>  
  <joint
    name="LF_foot_joint"
    type="fixed" dont_collapse="true">
    <origin
      xyz="0 0 -0.213"
      rpy="0 0 0" />
    <parent
      link="LF_SHANK" />
    <child
      link="LF_FOOT" />
    <axis
      xyz="0 0 0" />
  </joint>  
  <link name="LF_FOOT">
    <inertial>
      <origin
        xyz="0 0 0"
        rpy="0 0 0" />
      <mass
        value="0.04" />
      <inertia
        ixx="9.6e-06"
        ixy="0"
        ixz="0"
        iyy="9.6e-06"
        iyz="0"
        izz="9.6e-06" />
    </inertial>
    <visual>
      <origin
        xyz="0 0 0"
        rpy="0 0 0" />
      <geometry>
        <mesh
          filename="package://ocs2_robotic_assets/resources/go2/dae/foot.dae" />
      </geometry>
      <material
        name="">
        <color
          rgba="1 1 1 1" />
      </material>
    </visual>
    <collision>
      <origin rpy="0 0 0" xyz="-0.002 0 0" />
      <geometry>
        <sphere radius="0.022" />
      </geometry>
    </collision>
  </link>

  <!-- FRONT RIGHT LEG -->
  <joint name="RF_HAA" type="revolute">
    <parent link="base" />
    <child link="RF_HIP" />
    <origin
      xyz="0.1934 -0.0465 0"
      rpy="0 0 0" />
    <axis xyz="1 0 0" />
    <limit
      lower="-1.0472"
      upper="1.0472"
      effort="23.7"
      velocity="30.1" />
  </joint>
  <link name="RF_HIP">
    <inertial>
      <origin
        xyz="-0.0054 -0.00194 -0.000105"
        rpy="0 0 0" />
      <mass
        value="0.678" />
      <inertia
        ixx="0.00048"
        ixy="3.01E-06"
        ixz="1.11E-06"
        iyy="0.000884"
        iyz="1.42E-06"
        izz="0.000596" />
    </inertial>
    <visual>
      <origin
        xyz="0 0 0"
        rpy="3.1415 0 0" />
      <geometry>
        <mesh
          filename="package://ocs2_robotic_assets/resources/go2/dae/hip.dae" />
      </geometry>
      <material
        name="">
        <color
          rgba="1 1 1 1" />
      </material>
    </visual>
    <collision>
      <origin rpy="1.5707963267948966 0 0" xyz="0 -0.08 0" />
      <geometry>
        <cylinder length="0.04" radius="0.046" />
      </geometry>
    </collision>
  </link>
  <joint name="RF_HFE" type="revolute">
    <parent
      link="RF_HIP" />
    <child
      link="RF_THIGH" />
    <origin
      xyz="0 -0.0955 0"
      rpy="0 0 0" />
    <axis
      xyz="0 1 0" />
    <limit
      lower="-1.5708"
      upper="3.4907"
      effort="23.7"
      velocity="30.1" />
  </joint>
  <link name="RF_THIGH">
    <inertial>
      <origin
        xyz="-0.00374 0.0223 -0.0327"
        rpy="0 0 0" />
      <mass
        value="1.152" />
      <inertia
        ixx="0.00584"
        ixy="-8.72E-05"
        ixz="-0.000289"
        iyy="0.0058"
        iyz="-0.000808"
        izz="0.00103" />
    </inertial>
    <visual>
      <origin
        xyz="0 0 0"
        rpy="0 0 0" />
      <geometry>
        <mesh
          filename="package://ocs2_robotic_assets/resources/go2/dae/thigh_mirror.dae" />
      </geometry>
      <material
        name="">
        <color
          rgba="1 1 1 1" />
      </material>
    </visual>
    <collision>
      <origin rpy="0 1.5707963267948966 0" xyz="0 0 -0.1065" />
      <geometry>
        <box size="0.213 0.0245 0.034" />
      </geometry>
    </collision>
  </link>  
  <joint name="RF_KFE" type="revolute">
    <origin
      xyz="0 0 -0.213"
      rpy="0 0 0" />
    <parent
      link="RF_THIGH" />
    <child
      link="RF_SHANK" />
    <axis
      xyz="0 1 0" />
    <limit
      lower="-2.7227"
      upper="-0.83776"
      effort="45.43"
      velocity="15.70" />
  </joint>
  <link name="RF_SHANK">
    <inertial>
      <origin
        xyz="0.00548 0.000975 -0.115"
        rpy="0 0 0" />
      <mass
        value="0.154" />
      <inertia
        ixx="0.00108"
        ixy="-3.4E-07"
        ixz="1.72E-05"
        iyy="0.0011"
        iyz="-8.28E-06"
        izz="3.29E-05" />
    </inertial>
    <visual>
      <origin
        xyz="0 0 0"
        rpy="0 0 0" />
      <geometry>
        <mesh
          filename="package://ocs2_robotic_assets/resources/go2/dae/calf_mirror.dae" />
      </geometry>
      <material
        name="">
        <color
          rgba="1 1 1 1" />
      </material>
    </visual>
    <collision>
      <origin rpy="0 -0.2 0" xyz="0.01 0 -0.06" />
      <geometry>
        <cylinder length="0.12" radius="0.013" />
      </geometry>
    </collision>
  </link>  
  <link
    name="RF_calflower">
    <collision>
      <origin rpy="0 0 0" xyz="0 0 0" />
      <geometry>
        <cylinder length="0.065" radius="0.011" />
      </geometry>
    </collision>
  </link>
  <joint
    name="RF_calflower_joint"
    type="fixed">
    <origin
      xyz="0.020 0 -0.148"
      rpy="0 0.05 0" />
    <parent
      link="RF_SHANK" />
    <child
      link="RF_calflower" />
    <axis
      xyz="0 0 0" />
  </joint>
  <link
    name="RF_calflower1">
    <collision>
      <origin rpy="0 0 0" xyz="0 0 0" />
      <geometry>
        <cylinder length="0.03" radius="0.0155" />
      </geometry>
    </collision>
  </link>
  <joint
    name="RF_calflower1_joint"
    type="fixed">
    <origin
      xyz="-0.01 0 -0.04"
      rpy="0 0.48 0" />
    <parent
      link="RF_calflower" />
    <child
      link="RF_calflower1" />
    <axis
      xyz="0 0 0" />
  </joint>  
  <joint
    name="RF_foot_joint"
    type="fixed" dont_collapse="true">
    <origin
      xyz="0 0 -0.213"
      rpy="0 0 0" />
    <parent
      link="RF_SHANK" />
    <child
      link="RF_FOOT" />
    <axis
      xyz="0 0 0" />
  </joint>  
  <link name="RF_FOOT">
    <inertial>
      <origin
        xyz="0 0 0"
        rpy="0 0 0" />
      <mass
        value="0.04" />
      <inertia
        ixx="9.6e-06"
        ixy="0"
        ixz="0"
        iyy="9.6e-06"
        iyz="0"
        izz="9.6e-06" />
    </inertial>
    <visual>
      <origin
        xyz="0 0 0"
        rpy="0 0 0" />
      <geometry>
        <mesh
          filename="package://ocs2_robotic_assets/resources/go2/dae/foot.dae" />
      </geometry>
      <material
        name="">
        <color
          rgba="1 1 1 1" />
      </material>
    </visual>
    <collision>
      <origin rpy="0 0 0" xyz="-0.002 0 0" />
      <geometry>
        <sphere radius="0.022" />
      </geometry>
    </collision>
  </link>
  
  <!-- HIND LEFT LEG -->
  <joint name="LH_HAA" type="revolute">
    <parent link="base" />
    <child link="LH_HIP" />
    <origin
      xyz="-0.1934 0.0465 0"
      rpy="0 0 0" />
    <axis xyz="1 0 0" />
    <limit
      lower="-1.0472"
      upper="1.0472"
      effort="23.7"
      velocity="30.1" />
  </joint>
  <link name="LH_HIP">
    <inertial>
      <origin
        xyz="0.0054 0.00194 -0.000105"
        rpy="0 0 0" />
      <mass
        value="0.678" />
      <inertia
        ixx="0.00048"
        ixy="3.01E-06"
        ixz="-1.11E-06"
        iyy="0.000884"
        iyz="-1.42E-06"
        izz="0.000596" />
    </inertial>
    <visual>
      <origin
        xyz="0 0 0"
        rpy="0 3.1415 0" />
      <geometry>
        <mesh
          filename="package://ocs2_robotic_assets/resources/go2/dae/hip.dae" />
      </geometry>
      <material
        name="">
        <color
          rgba="1 1 1 1" />
      </material>
    </visual>
    <collision>
      <origin rpy="1.5707963267948966 0 0" xyz="0 0.08 0" />
      <geometry>
        <cylinder length="0.04" radius="0.046" />
      </geometry>
    </collision>
  </link>
  <joint name="LH_HFE" type="revolute">
    <parent
      link="LH_HIP" />
    <child
      link="LH_THIGH" />
    <origin
      xyz="0 0.0955 0"
      rpy="0 0 0" />
    <axis
      xyz="0 1 0" />
    <limit
      lower="-0.5236"
      upper="4.5379"
      effort="23.7"
      velocity="30.1" />
  </joint>
  <link name="LH_THIGH">
    <inertial>
      <origin
        xyz="-0.00374 -0.0223 -0.0327"
        rpy="0 0 0" />
      <mass
        value="1.152" />
      <inertia
        ixx="0.00584"
        ixy="8.72E-05"
        ixz="-0.000289"
        iyy="0.0058"
        iyz="0.000808"
        izz="0.00103" />
    </inertial>
    <visual>
      <origin
        xyz="0 0 0"
        rpy="0 0 0" />
      <geometry>
        <mesh
          filename="package://ocs2_robotic_assets/resources/go2/dae/thigh.dae" />
      </geometry>
      <material
        name="">
        <color
          rgba="1 1 1 1" />
      </material>
    </visual>
    <collision>
      <origin rpy="0 1.5707963267948966 0" xyz="0 0 -0.1065" />
      <geometry>
        <box size="0.213 0.0245 0.034" />
      </geometry>
    </collision>
  </link>  
  <joint name="LH_KFE" type="revolute">
    <origin
      xyz="0 0 -0.213"
      rpy="0 0 0" />
    <parent
      link="LH_THIGH" />
    <child
      link="LH_SHANK" />
    <axis
      xyz="0 1 0" />
    <limit
      lower="-2.7227"
      upper="-0.83776"
      effort="45.43"
      velocity="15.70" />
  </joint>
  <link name="LH_SHANK">
    <inertial>
      <origin
        xyz="0.00548 -0.000975 -0.115"
        rpy="0 0 0" />
      <mass
        value="0.154" />
      <inertia
        ixx="0.00108"
        ixy="3.4E-07"
        ixz="1.72E-05"
        iyy="0.0011"
        iyz="8.28E-06"
        izz="3.29E-05" />
    </inertial>
    <visual>
      <origin
        xyz="0 0 0"
        rpy="0 0 0" />
      <geometry>
        <mesh
          filename="package://ocs2_robotic_assets/resources/go2/dae/calf.dae" />
      </geometry>
      <material
        name="">
        <color
          rgba="1 1 1 1" />
      </material>
    </visual>
    <collision>
      <origin rpy="0 -0.2 0" xyz="0.01 0 -0.06" />
      <geometry>
        <cylinder length="0.12" radius="0.013" />
      </geometry>
    </collision>
  </link>
  <link
    name="LH_calflower">
    <collision>
      <origin rpy="0 0 0" xyz="0 0 0" />
      <geometry>
        <cylinder length="0.065" radius="0.011" />
      </geometry>
    </collision>
  </link>
  <joint
    name="LH_calflower_joint"
    type="fixed">
    <origin
      xyz="0.020 0 -0.148"
      rpy="0 0.05 0" />
    <parent
      link="LH_SHANK" />
    <child
      link="LH_calflower" />
    <axis
      xyz="0 0 0" />
  </joint>
  <link
    name="LH_calflower1">
    <collision>
      <origin rpy="0 0 0" xyz="0 0 0" />
      <geometry>
        <cylinder length="0.03" radius="0.0155" />
      </geometry>
    </collision>
  </link>
  <joint
    name="LH_calflower1_joint"
    type="fixed">
    <origin
      xyz="-0.01 0 -0.04"
      rpy="0 0.48 0" />
    <parent
      link="LH_calflower" />
    <child
      link="LH_calflower1" />
    <axis
      xyz="0 0 0" />
  </joint>  
  <joint
    name="LH_foot_joint"
    type="fixed" dont_collapse="true">
    <origin
      xyz="0 0 -0.213"
      rpy="0 0 0" />
    <parent
      link="LH_SHANK" />
    <child
      link="LH_FOOT" />
    <axis
      xyz="0 0 0" />
  </joint>  
  <link name="LH_FOOT">
    <inertial>
      <origin
        xyz="0 0 0"
        rpy="0 0 0" />
      <mass
        value="0.04" />
      <inertia
        ixx="9.6e-06"
        ixy="0"
        ixz="0"
        iyy="9.6e-06"
        iyz="0"
        izz="9.6e-06" />
    </inertial>
    <visual>
      <origin
        xyz="0 0 0"
        rpy="0 0 0" />
      <geometry>
        <mesh
          filename="package://ocs2_robotic_assets/resources/go2/dae/foot.dae" />
      </geometry>
      <material
        name="">
        <color
          rgba="1 1 1 1" />
      </material>
    </visual>
    <collision>
      <origin rpy="0 0 0" xyz="-0.002 0 0" />
      <geometry>
        <sphere radius="0.022" />
      </geometry>
    </collision>
  </link>

  <!-- 
  <joint name="base_LH_HAA_drive" type="fixed">
    <parent link="base"/>
    <child link="LH_HAA_drive"/>
    <origin rpy="0 0 -3.141592653589793" xyz="-0.304 0.109 0.0"/>
  </joint>
  <link name="LH_HAA_drive">
    <visual>
      <origin rpy="0 0 0" xyz="0 0 0"/>
      <geometry>
        <mesh filename="package://ocs2_robotic_assets/resources/go2/meshes/drive.dae" scale="1.0 1.0 1.0"/>
      </geometry>
    </visual>
    <inertial>
      <origin rpy="0 0 0" xyz="-0.05783 -0.00014 0.00036"/>
      <mass value="2.01511"/>
      <inertia ixx="0.0033251482" ixy="2.567315e-05" ixz="2.599963e-05" iyy="0.00318377804" iyz="9.462185e-05" izz="0.00355095312"/>
    </inertial>
  </link>
  <joint name="LH_HAA" type="revolute">
    <parent link="LH_HAA_drive"/>
    <child link="LH_HIP"/>
    <origin rpy="0 0 0" xyz="0 0 0"/>
    <axis xyz="-1 0 0"/>
    <limit command_effort="80.0" current="32.0" effort="80.0" gear_velocity="8.5" lower="-0.7853985" upper="0.6108655" velocity="8.5"/>
    <dynamics damping="0.0" friction="0.0"/>
  </joint>
  <link name="LH_HIP">
    <inertial>
      <origin rpy="0 0 0" xyz="0 0 0"/>
      <mass value="0.001"/>
      <inertia ixx="0.000001" ixy="0.0" ixz="0.0" iyy="0.000001" iyz="0.0" izz="0.000001"/>
    </inertial>
  </link>
  <joint name="LH_HIP_LH_hip_fixed" type="fixed">
    <parent link="LH_HIP"/>
    <child link="LH_hip_fixed"/>
    <origin rpy="0 0 -3.141592653589793" xyz="0 0 0"/>
  </joint>
  <link name="LH_hip_fixed">
    <visual>
      <origin rpy="-3.141592653589793 0 -3.141592653589793" xyz="0 0 0"/>
      <geometry>
        <mesh filename="package://ocs2_robotic_assets/resources/go2/meshes/hip.dae" scale="1.0 1.0 1.0"/>
      </geometry>
    </visual>
    <inertial>
      <origin rpy="0 0 0" xyz="-0.03505 -0.00125 0.0"/>
      <mass value="0.36386"/>
      <inertia ixx="0.00023646957" ixy="-3.45771e-06" ixz="-1.268e-08" iyy="0.00055386457" iyz="1.811e-08" izz="0.00043888609"/>
    </inertial>
  </link>
  <joint name="LH_hip_fixed_LH_HFE_output" type="fixed">
    <parent link="LH_hip_fixed"/>
    <child link="LH_HFE_output"/>
    <origin rpy="0 0 -1.5707963267948966" xyz="-0.069 0.006 0.0"/>
  </joint>
  <link name="LH_HFE_output">
    <inertial>
      <origin rpy="0 0 0" xyz="0 0 0"/>
      <mass value="0.001"/>
      <inertia ixx="0.000001" ixy="0.0" ixz="0.0" iyy="0.000001" iyz="0.0" izz="0.000001"/>
    </inertial>
  </link>
  <link name="LH_HFE_drive">
    <visual>
      <origin rpy="0 0 0" xyz="0 0 0"/>
      <geometry>
        <mesh filename="package://ocs2_robotic_assets/resources/go2/meshes/drive.dae" scale="1.0 1.0 1.0"/>
      </geometry>
    </visual>
    <collision>
      <origin rpy="0 1.5707963267948966 0" xyz="-0.0595 0 0"/>
      <geometry>
        <cylinder length="0.119" radius="0.05375"/>
      </geometry>
    </collision>
    <inertial>
      <origin rpy="0 0 0" xyz="-0.05783 -0.00014 0.00036"/>
      <mass value="2.01511"/>
      <inertia ixx="0.0033251482" ixy="2.567315e-05" ixz="2.599963e-05" iyy="0.00318377804" iyz="9.462185e-05" izz="0.00355095312"/>
    </inertial>
  </link>
  <joint name="LH_HFE" type="revolute">
    <parent link="LH_HFE_output"/>
    <child link="LH_THIGH"/>
    <origin rpy="0 0 0" xyz="0 0 0"/>
    <axis xyz="-1 0 0"/>
    <limit command_effort="80.0" current="32.0" effort="80.0" gear_velocity="8.5" lower="-9.42477796076938" upper="9.42477796076938" velocity="8.5"/>
    <dynamics damping="0.0" friction="0.0"/>
  </joint>
  <link name="LH_THIGH">
    <inertial>
      <origin rpy="0 0 0" xyz="0 0 0"/>
      <mass value="0.001"/>
      <inertia ixx="0.000001" ixy="0.0" ixz="0.0" iyy="0.000001" iyz="0.0" izz="0.000001"/>
    </inertial>
  </link>
  <joint name="LH_THIGH_to_LH_HFE_drive" type="fixed">
    <parent link="LH_THIGH"/>
    <child link="LH_HFE_drive"/>
    <origin rpy="0 0 0" xyz="0 0 0"/>
  </joint>
  <joint name="LH_HFE_drive_LH_thigh_fixed" type="fixed">
    <parent link="LH_HFE_drive"/>
    <child link="LH_thigh_fixed"/>
    <origin rpy="0 0 1.5707963267948966" xyz="0 0 0"/>
  </joint>
  <link name="LH_thigh_fixed">
    <visual>
      <origin rpy="0 0 0.0" xyz="0 0 0"/>
      <geometry>
        <mesh filename="package://ocs2_robotic_assets/resources/go2/meshes/thigh.dae" scale="1.0 1.0 1.0"/>
      </geometry>
    </visual>
        <collision>
      <origin rpy="1.5707963267948966 0 0" xyz="0 0.10519500000000001 0"/>
      <geometry>
        <cylinder length="0.08313000000000001" radius="0.07"/>
      </geometry>
    </collision>
    <collision>
      <origin rpy="0 0 0" xyz="0 0.09513 -0.1425"/>
      <geometry>
        <box size="0.093 0.063 0.285"/>
      </geometry>
    </collision>
    <collision>
      <origin rpy="1.5707963267948966 0 0" xyz="0 0.08506500000000002 -0.285"/>
      <geometry>
        <cylinder length="0.08313000000000001" radius="0.07"/>
      </geometry>
    </collision>
    <inertial>
      <origin rpy="0 0 0" xyz="0.00041 0.09155 -0.13317"/>
      <mass value="1.10098"/>
      <inertia ixx="0.01541669135" ixy="-0.00021116021" ixz="-0.00031942961" iyy="0.01630081575" iyz="0.00143783119" izz="0.00258410631"/>
    </inertial>
  </link>
  <joint name="LH_thigh_fixed_LH_KFE_drive" type="fixed">
    <parent link="LH_thigh_fixed"/>
    <child link="LH_KFE_drive"/>
    <origin rpy="0 0 1.5707963267948966" xyz="-0.0 0.1805 -0.285"/>
  </joint>
  <link name="LH_KFE_drive">
    <visual>
      <origin rpy="0 0 0" xyz="0 0 0"/>
      <geometry>
        <mesh filename="package://ocs2_robotic_assets/resources/go2/meshes/drive.dae" scale="1.0 1.0 1.0"/>
      </geometry>
    </visual>
    <collision>
      <origin rpy="0 1.5707963267948966 0" xyz="-0.0595 0 0"/>
      <geometry>
        <cylinder length="0.119" radius="0.05375"/>
      </geometry>
    </collision>
    <inertial>
      <origin rpy="0 0 0" xyz="-0.05783 -0.00014 0.00036"/>
      <mass value="2.01511"/>
      <inertia ixx="0.0033251482" ixy="2.567315e-05" ixz="2.599963e-05" iyy="0.00318377804" iyz="9.462185e-05" izz="0.00355095312"/>
    </inertial>
  </link>
  <joint name="LH_KFE" type="revolute">
    <parent link="LH_KFE_drive"/>
    <child link="LH_SHANK"/>
    <origin rpy="0 0 0" xyz="0 0 0"/>
    <axis xyz="1 0 0"/>
    <limit command_effort="80.0" current="32.0" effort="80.0" gear_velocity="8.5" lower="-9.42477796076938" upper="9.42477796076938" velocity="8.5"/>
    <dynamics damping="0.0" friction="0.0"/>
  </joint>
  <link name="LH_SHANK">
    <inertial>
      <origin rpy="0 0 0" xyz="0 0 0"/>
      <mass value="0.001"/>
      <inertia ixx="0.000001" ixy="0.0" ixz="0.0" iyy="0.000001" iyz="0.0" izz="0.000001"/>
    </inertial>
  </link>
  <joint name="LH_shank_LH_shank_fixed" type="fixed">
    <parent link="LH_SHANK"/>
    <child link="LH_shank_fixed"/>
    <origin rpy="0 0 -1.5707963267948966" xyz="0 0 0"/>
  </joint>
  <link name="LH_shank_fixed">
    <visual>
      <origin rpy="0 0 -3.141592653589793" xyz="0 0 0"/>
      <geometry>
        <mesh filename="package://ocs2_robotic_assets/resources/go2/meshes/shank_r.dae" scale="1.0 1.0 1.0"/>
      </geometry>
    </visual>
        <collision>
      <origin rpy="1.5707963267948966 0 0" xyz="0 0 0"/>
      <geometry>
        <cylinder length="0.05732" radius="0.071"/>
      </geometry>
    </collision>
    <collision>
      <origin rpy="1.5707963267948966 0 0" xyz="-0.066415 0 0"/>
      <geometry>
        <box size="0.13283 0.08302 0.05732"/>
      </geometry>
    </collision>
    <inertial>
      <origin rpy="0 0 0" xyz="-0.02186 0.00895 0.00042"/>
      <mass value="0.49854"/>
      <inertia ixx="0.00054939614" ixy="-2.147115e-05" ixz="-1.687902e-05" iyy="0.00166971314" iyz="1.71584e-06" izz="0.00127258622"/>
    </inertial>
  </link>
  <joint name="LH_shank_fixed_LH_FOOT" type="fixed">
    <parent link="LH_shank_fixed"/>
    <child link="LH_FOOT"/>
    <origin rpy="0 0 0" xyz="-0.1 0.02225 -0.39246"/>
  </joint>
  <link name="LH_FOOT">
    <visual>
      <origin rpy="0 0 0.0" xyz="0 0 0"/>
      <geometry>
        <mesh filename="package://ocs2_robotic_assets/resources/go2/meshes/foot.dae" scale="1.0 1.0 1.0"/>
      </geometry>
    </visual>
        <collision>
      <origin rpy="0 0 0" xyz="0 -0.016891153063699788 0.22824319686592265"/>
      <geometry>
        <cylinder length="0.39572" radius="0.0175"/>
      </geometry>
    </collision>
        <collision>
      <origin xyz="0 -0.008141153063699788 0.03038319686592264"/>
      <geometry>
        <sphere radius="0.031455"/>
      </geometry>
    </collision>
    <inertial>
      <origin rpy="0 0 0" xyz="-0.0 -0.01559 0.15004"/>
      <mass value="0.29644"/>
      <inertia ixx="0.00514263169" ixy="-1.46e-09" ixz="-6.85e-09" iyy="0.0051315957" iyz="0.00016323086" izz="0.00011890148"/>
    </inertial>
  </link> -->

  <joint name="base_RH_HAA_drive" type="fixed">
    <parent link="base"/>
    <child link="RH_HAA_drive"/>
    <origin rpy="0 0 -3.141592653589793" xyz="-0.304 -0.109 0.0"/>
  </joint>
  <link name="RH_HAA_drive">
    <visual>
      <origin rpy="0 0 0" xyz="0 0 0"/>
      <geometry>
        <mesh filename="package://ocs2_robotic_assets/resources/go2/meshes/drive.dae" scale="1.0 1.0 1.0"/>
      </geometry>
    </visual>
    <inertial>
      <origin rpy="0 0 0" xyz="-0.05783 -0.00014 0.00036"/>
      <mass value="2.01511"/>
      <inertia ixx="0.0033251482" ixy="2.567315e-05" ixz="2.599963e-05" iyy="0.00318377804" iyz="9.462185e-05" izz="0.00355095312"/>
    </inertial>
  </link>
  <joint name="RH_HAA" type="revolute">
    <parent link="RH_HAA_drive"/>
    <child link="RH_HIP"/>
    <origin rpy="0 0 0" xyz="0 0 0"/>
    <axis xyz="-1 0 0"/>
    <limit command_effort="80.0" current="32.0" effort="80.0" gear_velocity="8.5" lower="-0.6108655" upper="0.7853985" velocity="8.5"/>
    <dynamics damping="0.0" friction="0.0"/>
  </joint>
  <link name="RH_HIP">
    <inertial>
      <origin rpy="0 0 0" xyz="0 0 0"/>
      <mass value="0.001"/>
      <inertia ixx="0.000001" ixy="0.0" ixz="0.0" iyy="0.000001" iyz="0.0" izz="0.000001"/>
    </inertial>
  </link>
  <joint name="RH_HIP_RH_hip_fixed" type="fixed">
    <parent link="RH_HIP"/>
    <child link="RH_hip_fixed"/>
    <origin rpy="0 0 -3.141592653589793" xyz="0 0 0"/>
  </joint>
  <link name="RH_hip_fixed">
    <visual>
      <origin rpy="0.0 0 -3.141592653589793" xyz="0 0 0"/>
      <geometry>
        <mesh filename="package://ocs2_robotic_assets/resources/go2/meshes/hip.dae" scale="1.0 1.0 1.0"/>
      </geometry>
    </visual>
    <inertial>
      <origin rpy="0 0 0" xyz="-0.03505 0.00125 0.0"/>
      <mass value="0.36386"/>
      <inertia ixx="0.00023646957" ixy="3.45771e-06" ixz="-1.268e-08" iyy="0.00055386457" iyz="-1.811e-08" izz="0.00043888609"/>
    </inertial>
  </link>
  <joint name="RH_hip_fixed_RH_HFE_output" type="fixed">
    <parent link="RH_hip_fixed"/>
    <child link="RH_HFE_output"/>
    <origin rpy="0 0 1.5707963267948966" xyz="-0.069 -0.006 0.0"/>
  </joint>
  <link name="RH_HFE_output">
    <inertial>
      <origin rpy="0 0 0" xyz="0 0 0"/>
      <mass value="0.001"/>
      <inertia ixx="0.000001" ixy="0.0" ixz="0.0" iyy="0.000001" iyz="0.0" izz="0.000001"/>
    </inertial>
  </link>
  <link name="RH_HFE_drive">
    <visual>
      <origin rpy="0 0 0" xyz="0 0 0"/>
      <geometry>
        <mesh filename="package://ocs2_robotic_assets/resources/go2/meshes/drive.dae" scale="1.0 1.0 1.0"/>
      </geometry>
    </visual>
    <collision>
      <origin rpy="0 1.5707963267948966 0" xyz="-0.0595 0 0"/>
      <geometry>
        <cylinder length="0.119" radius="0.05375"/>
      </geometry>
    </collision>
    <inertial>
      <origin rpy="0 0 0" xyz="-0.05783 -0.00014 0.00036"/>
      <mass value="2.01511"/>
      <inertia ixx="0.0033251482" ixy="2.567315e-05" ixz="2.599963e-05" iyy="0.00318377804" iyz="9.462185e-05" izz="0.00355095312"/>
    </inertial>
  </link>
  <joint name="RH_HFE" type="revolute">
    <parent link="RH_HFE_output"/>
    <child link="RH_THIGH"/>
    <origin rpy="0 0 0" xyz="0 0 0"/>
    <axis xyz="1 0 0"/>
    <limit command_effort="80.0" current="32.0" effort="80.0" gear_velocity="8.5" lower="-9.42477796076938" upper="9.42477796076938" velocity="8.5"/>
    <dynamics damping="0.0" friction="0.0"/>
  </joint>
  <link name="RH_THIGH">
    <inertial>
      <origin rpy="0 0 0" xyz="0 0 0"/>
      <mass value="0.001"/>
      <inertia ixx="0.000001" ixy="0.0" ixz="0.0" iyy="0.000001" iyz="0.0" izz="0.000001"/>
    </inertial>
  </link>
  <joint name="RH_THIGH_to_RH_HFE_drive" type="fixed">
    <parent link="RH_THIGH"/>
    <child link="RH_HFE_drive"/>
    <origin rpy="0 0 0" xyz="0 0 0"/>
  </joint>
  <joint name="RH_HFE_drive_RH_thigh_fixed" type="fixed">
    <parent link="RH_HFE_drive"/>
    <child link="RH_thigh_fixed"/>
    <origin rpy="0 0 -1.5707963267948966" xyz="0 0 0"/>
  </joint>
  <link name="RH_thigh_fixed">
    <visual>
      <origin rpy="0 0 -3.141592653589793" xyz="0 0 0"/>
      <geometry>
        <mesh filename="package://ocs2_robotic_assets/resources/go2/meshes/thigh.dae" scale="1.0 1.0 1.0"/>
      </geometry>
    </visual>
        <collision>
      <origin rpy="1.5707963267948966 0 0" xyz="0 -0.10519500000000001 0"/>
      <geometry>
        <cylinder length="0.08313000000000001" radius="0.07"/>
      </geometry>
    </collision>
    <collision>
      <origin rpy="0 0 0" xyz="0 -0.09513 -0.1425"/>
      <geometry>
        <box size="0.093 0.063 0.285"/>
      </geometry>
    </collision>
    <collision>
      <origin rpy="1.5707963267948966 0 0" xyz="0 -0.08506500000000002 -0.285"/>
      <geometry>
        <cylinder length="0.08313000000000001" radius="0.07"/>
      </geometry>
    </collision>
    <inertial>
      <origin rpy="0 0 0" xyz="0.00041 -0.09155 -0.13317"/>
      <mass value="1.10098"/>
      <inertia ixx="0.01541669135" ixy="0.00021116021" ixz="-0.00031942961" iyy="0.01630081575" iyz="-0.00143783119" izz="0.00258410631"/>
    </inertial>
  </link>
  <joint name="RH_thigh_fixed_RH_KFE_drive" type="fixed">
    <parent link="RH_thigh_fixed"/>
    <child link="RH_KFE_drive"/>
    <origin rpy="0 0 -1.5707963267948966" xyz="-0.0 -0.1805 -0.285"/>
  </joint>
  <link name="RH_KFE_drive">
    <visual>
      <origin rpy="0 0 0" xyz="0 0 0"/>
      <geometry>
        <mesh filename="package://ocs2_robotic_assets/resources/go2/meshes/drive.dae" scale="1.0 1.0 1.0"/>
      </geometry>
    </visual>
    <collision>
      <origin rpy="0 1.5707963267948966 0" xyz="-0.0595 0 0"/>
      <geometry>
        <cylinder length="0.119" radius="0.05375"/>
      </geometry>
    </collision>
    <inertial>
      <origin rpy="0 0 0" xyz="-0.05783 -0.00014 0.00036"/>
      <mass value="2.01511"/>
      <inertia ixx="0.0033251482" ixy="2.567315e-05" ixz="2.599963e-05" iyy="0.00318377804" iyz="9.462185e-05" izz="0.00355095312"/>
    </inertial>
  </link>
  <joint name="RH_KFE" type="revolute">
    <parent link="RH_KFE_drive"/>
    <child link="RH_SHANK"/>
    <origin rpy="0 0 0" xyz="0 0 0"/>
    <axis xyz="-1 0 0"/>
    <limit command_effort="80.0" current="32.0" effort="80.0" gear_velocity="8.5" lower="-9.42477796076938" upper="9.42477796076938" velocity="8.5"/>
    <dynamics damping="0.0" friction="0.0"/>
  </joint>
  <link name="RH_SHANK">
    <inertial>
      <origin rpy="0 0 0" xyz="0 0 0"/>
      <mass value="0.001"/>
      <inertia ixx="0.000001" ixy="0.0" ixz="0.0" iyy="0.000001" iyz="0.0" izz="0.000001"/>
    </inertial>
  </link>
  <joint name="RH_shank_RH_shank_fixed" type="fixed">
    <parent link="RH_SHANK"/>
    <child link="RH_shank_fixed"/>
    <origin rpy="0 0 1.5707963267948966" xyz="0 0 0"/>
  </joint>
  <link name="RH_shank_fixed">
    <visual>
      <origin rpy="0 0 -3.141592653589793" xyz="0 0 0"/>
      <geometry>
        <mesh filename="package://ocs2_robotic_assets/resources/go2/meshes/shank_l.dae" scale="1.0 1.0 1.0"/>
      </geometry>
    </visual>
        <collision>
      <origin rpy="1.5707963267948966 0 0" xyz="0 0 0"/>
      <geometry>
        <cylinder length="0.05732" radius="0.071"/>
      </geometry>
    </collision>
    <collision>
      <origin rpy="1.5707963267948966 0 0" xyz="-0.066415 0 0"/>
      <geometry>
        <box size="0.13283 0.08302 0.05732"/>
      </geometry>
    </collision>
    <inertial>
      <origin rpy="0 0 0" xyz="-0.02186 -0.00895 0.00042"/>
      <mass value="0.49854"/>
      <inertia ixx="0.00054939614" ixy="2.147115e-05" ixz="-1.687902e-05" iyy="0.00166971314" iyz="-1.71584e-06" izz="0.00127258622"/>
    </inertial>
  </link>
  <joint name="RH_shank_fixed_RH_FOOT" type="fixed">
    <parent link="RH_shank_fixed"/>
    <child link="RH_FOOT"/>
    <origin rpy="0 0 0" xyz="-0.1 -0.02225 -0.39246"/>
  </joint>
  <link name="RH_FOOT">
    <visual>
      <origin rpy="0 0 -3.141592653589793" xyz="0 0 0"/>
      <geometry>
        <mesh filename="package://ocs2_robotic_assets/resources/go2/meshes/foot.dae" scale="1.0 1.0 1.0"/>
      </geometry>
    </visual>
        <collision>
      <origin rpy="0 0 0" xyz="0 0.016891153063699788 0.22824319686592265"/>
      <geometry>
        <cylinder length="0.39572" radius="0.0175"/>
      </geometry>
    </collision>
        <collision>
      <origin xyz="0 0.008141153063699788 0.03038319686592264"/>
      <geometry>
        <sphere radius="0.031455"/>
      </geometry>
    </collision>
    <inertial>
      <origin rpy="0 0 0" xyz="-0.0 0.01559 0.15004"/>
      <mass value="0.29644"/>
      <inertia ixx="0.00514263169" ixy="1.46e-09" ixz="-6.85e-09" iyy="0.0051315957" iyz="-0.00016323086" izz="0.00011890148"/>
    </inertial>
  </link>
</robot>
