<?xml version="1.0" encoding="utf-8"?>
<!-- =================================================================================== -->
<!--   Copyright 2023 ANYbotics, https://www.anybotics.com                               -->
<!-- =================================================================================== -->
<!-- This file contains the description of the ANYmal robot. -->
<robot name="anymal">
  <link name="base">
    <inertial>
      <origin xyz="0.021112 0 -0.005366" rpy="0 0 0" />
      <mass value="6.921" />
      <inertia
        ixx="0.02448"
        ixy="0.00012166"
        ixz="0.0014849"
        iyy="0.098077"
        iyz="-3.12E-05"
        izz="0.107" />
    </inertial>
    <visual>
      <origin xyz="0 0 0" rpy="0 0 0" />
      <geometry>
        <mesh filename="package://ocs2_robotic_assets/resources/go2/dae/base.dae" />
      </geometry>
      <material
        name="">
        <color
          rgba="1 1 1 1" />
      </material>
    </visual>
    <collision>
      <origin rpy="0 0 0" xyz="0 0 0" />
      <geometry>
        <box size="0.3762 0.0935 0.114" />
      </geometry>
    </collision>
  </link>
  <joint name="base_to_base_inertia" type="fixed">
    <parent link="base"/>
    <child link="base_inertia"/>
    <origin rpy="0 0 0" xyz="0 0 0"/>
  </joint>
  <link name="base_inertia">
    <inertial>
      <origin rpy="0 0 0" xyz="-0.02148 0.00173 -0.04417"/>
      <mass value="8.27629"/>
      <inertia ixx="0.06185585085" ixy="0.00052357046" ixz="-0.02204886469" iyy="0.46467853407" iyz="0.00058724812" izz="0.47162119244"/>
    </inertial>
  </link>
  <joint name="base_to_body_top" type="fixed">
    <parent link="base"/>
    <child link="body_top"/>
    <origin rpy="0 0 0" xyz="0 0 0.144"/>
  </joint>
  <link name="body_top"/>
  <joint name="base_top_shell" type="fixed">
    <parent link="base"/>
    <child link="top_shell"/>
    <origin rpy="0 0 0" xyz="0 0 0"/>
  </joint>
  <link name="top_shell">
    <visual>
      <origin rpy="0 0 0" xyz="0 0 0"/>
      <!-- <geometry>
        <mesh filename="package://ocs2_robotic_assets/resources/anymal_d/meshes/top_shell.dae" scale="1.0 1.0 1.0"/>
      </geometry> -->
      <geometry>
        <sphere radius="0.022" />
      </geometry>
    </visual>
    <inertial>
      <origin rpy="0 0 0" xyz="-0.0226 -0.00027 0.07263"/>
      <mass value="0.32381"/>
      <inertia ixx="0.00391191516" ixy="-1.078994e-05" ixz="-0.00048832706" iyy="0.01761096758" iyz="4.45768e-06" izz="0.02086102766"/>
    </inertial>
  </link>
  <joint name="base_bottom_shell" type="fixed">
    <parent link="base"/>
    <child link="bottom_shell"/>
    <origin rpy="0 0 0" xyz="0 0 0"/>
  </joint>
  <link name="bottom_shell">
    <visual>
      <origin rpy="0 0 0" xyz="0 0 0"/>
      <geometry>
        <sphere radius="0.022" />
      </geometry>
      <!-- <geometry>
        <mesh filename="package://ocs2_robotic_assets/resources/anymal_d/meshes/bottom_shell.dae" scale="1.0 1.0 1.0"/>
      </geometry> -->
    </visual>
    <inertial>
      <origin rpy="0 0 0" xyz="9e-05 0.0 -0.0705"/>
      <mass value="0.73783"/>
      <inertia ixx="0.00724251946" ixy="8.94306e-06" ixz="7.96806e-05" iyy="0.03457730959" iyz="4.87e-09" izz="0.04075819312"/>
    </inertial>
  </link>
  <joint name="base_face_front" type="fixed">
    <parent link="base"/>
    <child link="face_front"/>
    <origin rpy="0 0 -0.0" xyz="0.4087 0 0.0205"/>
  </joint>
  <link name="face_front">
    <inertial>
      <origin rpy="0 0 0" xyz="-0.0362 0.00223 -0.02808"/>
      <mass value="0.48634"/>
      <inertia ixx="0.00077413444" ixy="1.55433e-06" ixz="6.243539e-05" iyy="0.00076586537" iyz="4.61106e-06" izz="0.00055588292"/>
    </inertial>
  </link>
  <joint name="face_front_to_depth_camera_front_lower_camera" type="fixed">
    <parent link="face_front"/>
    <child link="depth_camera_front_lower_camera"/>
    <origin rpy="0.0 1.0471975511965976 0" xyz="-0.04028 -0.025 -0.08051"/>
  </joint>
  <link name="depth_camera_front_lower_camera">
    <inertial>
      <origin rpy="0 0 0" xyz="-0.00362 -0.01787 -0.00011"/>
      <mass value="0.06355"/>
      <inertia ixx="6.841545e-05" ixy="1.46667e-06" ixz="4.115e-08" iyy="5.2817e-06" iyz="8.039e-08" izz="6.669787e-05"/>
    </inertial>
  </link>
  <joint name="depth_camera_front_lower_camera_to_camera_parent" type="fixed">
    <parent link="depth_camera_front_lower_camera"/>
    <child link="depth_camera_front_lower_camera_parent"/>
    <origin rpy="3.141592653589793 0.0 0.0" xyz="0.0 0.0 0.0"/>
  </joint>
  <link name="depth_camera_front_lower_camera_parent"/>
  <joint name="depth_camera_front_lower_camera_parent_to_depth_frame" type="fixed">
    <parent link="depth_camera_front_lower_camera_parent"/>
    <child link="depth_camera_front_lower_depth_frame"/>
    <origin rpy="0.0 0.0 0.0" xyz="0.0 0.0 0.0"/>
  </joint>
  <link name="depth_camera_front_lower_depth_frame"/>
  <joint name="depth_camera_front_lower_camera_depth_to_depth_optical_frame" type="fixed">
    <parent link="depth_camera_front_lower_depth_frame"/>
    <child link="depth_camera_front_lower_depth_optical_frame"/>
    <origin rpy="-1.5707963267948966 0.0 -1.5707963267948966" xyz="0.0 0.0 0.0"/>
  </joint>
  <link name="depth_camera_front_lower_depth_optical_frame"/>
  <joint name="face_front_to_depth_camera_front_upper_camera" type="fixed">
    <parent link="face_front"/>
    <child link="depth_camera_front_upper_camera"/>
    <origin rpy="0.0 0.2617993877991494 0" xyz="-0.00993 -0.025 -0.04096"/>
  </joint>
  <link name="depth_camera_front_upper_camera">
    <inertial>
      <origin rpy="0 0 0" xyz="-0.00362 -0.01787 -0.00011"/>
      <mass value="0.06355"/>
      <inertia ixx="6.841545e-05" ixy="1.46667e-06" ixz="4.115e-08" iyy="5.2817e-06" iyz="8.039e-08" izz="6.669787e-05"/>
    </inertial>
  </link>
  <joint name="depth_camera_front_upper_camera_to_camera_parent" type="fixed">
    <parent link="depth_camera_front_upper_camera"/>
    <child link="depth_camera_front_upper_camera_parent"/>
    <origin rpy="3.141592653589793 0.0 0.0" xyz="0.0 0.0 0.0"/>
  </joint>
  <link name="depth_camera_front_upper_camera_parent"/>
  <joint name="depth_camera_front_upper_camera_parent_to_depth_frame" type="fixed">
    <parent link="depth_camera_front_upper_camera_parent"/>
    <child link="depth_camera_front_upper_depth_frame"/>
    <origin rpy="0.0 0.0 0.0" xyz="0.0 0.0 0.0"/>
  </joint>
  <link name="depth_camera_front_upper_depth_frame"/>
  <joint name="depth_camera_front_upper_camera_depth_to_depth_optical_frame" type="fixed">
    <parent link="depth_camera_front_upper_depth_frame"/>
    <child link="depth_camera_front_upper_depth_optical_frame"/>
    <origin rpy="-1.5707963267948966 0.0 -1.5707963267948966" xyz="0.0 0.0 0.0"/>
  </joint>
  <link name="depth_camera_front_upper_depth_optical_frame"/>
  <joint name="face_front_to_wide_angle_camera_front_camera" type="fixed">
    <parent link="face_front"/>
    <child link="wide_angle_camera_front_camera"/>
    <origin rpy="0 0 0" xyz="0.0 0.0 0.0"/>
  </joint>
  <link name="wide_angle_camera_front_camera"/>
  <joint name="wide_angle_camera_front_camera_to_camera_parent" type="fixed">
    <parent link="wide_angle_camera_front_camera"/>
    <child link="wide_angle_camera_front_camera_parent"/>
    <origin rpy="-1.5707963267948966 0.0 -1.5707963267948966" xyz="-0.00421 0.0 0.0"/>
  </joint>
  <link name="wide_angle_camera_front_camera_parent"/>
  <joint name="base_face_rear" type="fixed">
    <parent link="base"/>
    <child link="face_rear"/>
    <origin rpy="0 0 3.141592653589793" xyz="-0.4087 0 0.0205"/>
  </joint>
  <link name="face_rear">
    <inertial>
      <origin rpy="0 0 0" xyz="-0.0362 0.00223 -0.02808"/>
      <mass value="0.48634"/>
      <inertia ixx="0.00077413444" ixy="1.55433e-06" ixz="6.243539e-05" iyy="0.00076586537" iyz="4.61106e-06" izz="0.00055588292"/>
    </inertial>
  </link>
  <joint name="face_rear_to_depth_camera_rear_lower_camera" type="fixed">
    <parent link="face_rear"/>
    <child link="depth_camera_rear_lower_camera"/>
    <origin rpy="0.0 1.0471975511965976 0" xyz="-0.04028 -0.025 -0.08051"/>
  </joint>
  <link name="depth_camera_rear_lower_camera">
    <inertial>
      <origin rpy="0 0 0" xyz="-0.00362 -0.01787 -0.00011"/>
      <mass value="0.06355"/>
      <inertia ixx="6.841545e-05" ixy="1.46667e-06" ixz="4.115e-08" iyy="5.2817e-06" iyz="8.039e-08" izz="6.669787e-05"/>
    </inertial>
  </link>
  <joint name="depth_camera_rear_lower_camera_to_camera_parent" type="fixed">
    <parent link="depth_camera_rear_lower_camera"/>
    <child link="depth_camera_rear_lower_camera_parent"/>
    <origin rpy="3.141592653589793 0.0 0.0" xyz="0.0 0.0 0.0"/>
  </joint>
  <link name="depth_camera_rear_lower_camera_parent"/>
  <joint name="depth_camera_rear_lower_camera_parent_to_depth_frame" type="fixed">
    <parent link="depth_camera_rear_lower_camera_parent"/>
    <child link="depth_camera_rear_lower_depth_frame"/>
    <origin rpy="0.0 0.0 0.0" xyz="0.0 0.0 0.0"/>
  </joint>
  <link name="depth_camera_rear_lower_depth_frame"/>
  <joint name="depth_camera_rear_lower_camera_depth_to_depth_optical_frame" type="fixed">
    <parent link="depth_camera_rear_lower_depth_frame"/>
    <child link="depth_camera_rear_lower_depth_optical_frame"/>
    <origin rpy="-1.5707963267948966 0.0 -1.5707963267948966" xyz="0.0 0.0 0.0"/>
  </joint>
  <link name="depth_camera_rear_lower_depth_optical_frame"/>
  <joint name="face_rear_to_depth_camera_rear_upper_camera" type="fixed">
    <parent link="face_rear"/>
    <child link="depth_camera_rear_upper_camera"/>
    <origin rpy="0.0 0.2617993877991494 0" xyz="-0.00993 -0.025 -0.04096"/>
  </joint>
  <link name="depth_camera_rear_upper_camera">
    <inertial>
      <origin rpy="0 0 0" xyz="-0.00362 -0.01787 -0.00011"/>
      <mass value="0.06355"/>
      <inertia ixx="6.841545e-05" ixy="1.46667e-06" ixz="4.115e-08" iyy="5.2817e-06" iyz="8.039e-08" izz="6.669787e-05"/>
    </inertial>
  </link>
  <joint name="depth_camera_rear_upper_camera_to_camera_parent" type="fixed">
    <parent link="depth_camera_rear_upper_camera"/>
    <child link="depth_camera_rear_upper_camera_parent"/>
    <origin rpy="3.141592653589793 0.0 0.0" xyz="0.0 0.0 0.0"/>
  </joint>
  <link name="depth_camera_rear_upper_camera_parent"/>
  <joint name="depth_camera_rear_upper_camera_parent_to_depth_frame" type="fixed">
    <parent link="depth_camera_rear_upper_camera_parent"/>
    <child link="depth_camera_rear_upper_depth_frame"/>
    <origin rpy="0.0 0.0 0.0" xyz="0.0 0.0 0.0"/>
  </joint>
  <link name="depth_camera_rear_upper_depth_frame"/>
  <joint name="depth_camera_rear_upper_camera_depth_to_depth_optical_frame" type="fixed">
    <parent link="depth_camera_rear_upper_depth_frame"/>
    <child link="depth_camera_rear_upper_depth_optical_frame"/>
    <origin rpy="-1.5707963267948966 0.0 -1.5707963267948966" xyz="0.0 0.0 0.0"/>
  </joint>
  <link name="depth_camera_rear_upper_depth_optical_frame"/>  <joint name="face_rear_to_wide_angle_camera_rear_camera" type="fixed">
    <parent link="face_rear"/>
    <child link="wide_angle_camera_rear_camera"/>
    <origin rpy="0 0 0" xyz="0.0 0.0 0.0"/>
  </joint>
  <link name="wide_angle_camera_rear_camera"/>
  <joint name="wide_angle_camera_rear_camera_to_camera_parent" type="fixed">
    <parent link="wide_angle_camera_rear_camera"/>
    <child link="wide_angle_camera_rear_camera_parent"/>
    <origin rpy="-1.5707963267948966 0.0 -1.5707963267948966" xyz="-0.00421 0.0 0.0"/>
  </joint>
  <link name="wide_angle_camera_rear_camera_parent"/>
  <joint name="base_face_shell_front" type="fixed">
    <parent link="face_front"/>
    <child link="face_shell_front"/>
    <origin rpy="0 0 0" xyz="0 0 0"/>
  </joint>
  <link name="face_shell_front">
    <visual>
      <origin rpy="0 0 0" xyz="0 0 0"/>
      <!-- <geometry>
        <mesh filename="package://ocs2_robotic_assets/resources/anymal_d/meshes/face_shell.dae" scale="1.0 1.0 1.0"/>
      </geometry> -->
      <geometry>
        <sphere radius="0.022" />
      </geometry>
    </visual>
    <inertial>
      <origin rpy="0 0 0" xyz="0.01446 4e-05 -0.01698"/>
      <mass value="0.1369"/>
      <inertia ixx="0.00102140404" ixy="9.54e-09" ixz="4.343039e-05" iyy="0.00051576362" iyz="2.7592e-07" izz="0.00057208503"/>
    </inertial>
  </link>
  <joint name="base_face_shell_rear" type="fixed">
    <parent link="face_rear"/>
    <child link="face_shell_rear"/>
    <origin rpy="0 0 0" xyz="0 0 0"/>
  </joint>
  <link name="face_shell_rear">
    <visual>
      <origin rpy="0 0 0" xyz="0 0 0"/>
      <!-- <geometry>
        <mesh filename="package://ocs2_robotic_assets/resources/anymal_d/meshes/face_shell.dae" scale="1.0 1.0 1.0"/>
      </geometry> -->
      <geometry>
        <sphere radius="0.022" />
      </geometry>
    </visual>
    <inertial>
      <origin rpy="0 0 0" xyz="0.01446 4e-05 -0.01698"/>
      <mass value="0.1369"/>
      <inertia ixx="0.00102140404" ixy="9.54e-09" ixz="4.343039e-05" iyy="0.00051576362" iyz="2.7592e-07" izz="0.00057208503"/>
    </inertial>
  </link>
  <joint name="base_battery" type="fixed">
    <parent link="base"/>
    <child link="battery"/>
    <origin rpy="0 0 0" xyz="0 0 0"/>
  </joint>
  <link name="battery">
    <visual>
      <origin rpy="0 0 0" xyz="0 0 0"/>
      <!-- <geometry>
        <mesh filename="package://ocs2_robotic_assets/resources/anymal_d/meshes/battery.dae" scale="1.0 1.0 1.0"/>
      </geometry> -->
      <geometry>
        <sphere radius="0.022" />
      </geometry>
    </visual>
    <inertial>
      <origin rpy="0 0 0" xyz="-0.00067 0.00023 -0.02212"/>
      <mass value="5.51206"/>
      <inertia ixx="0.00745533705" ixy="-0.00016412238" ixz="7.454512e-05" iyy="0.07199300212" iyz="-1.31605e-06" izz="0.07459357231"/>
    </inertial>
  </link>
  <joint name="base_to_docking_socket" type="fixed">
    <parent link="base"/>
    <child link="docking_socket"/>
    <origin rpy="0 0 0" xyz="0.26132 0.0 -0.06205"/>
  </joint>
  <link name="docking_socket">
    <visual>
      <origin rpy="0 0 0" xyz="0 0 0"/>
      <!-- <geometry>
        <mesh filename="package://ocs2_robotic_assets/resources/anymal_d/meshes/docking_socket.dae" scale="1.0 1.0 1.0"/>
      </geometry> -->
      <geometry>
        <sphere radius="0.022" />
      </geometry>
    </visual>
    <inertial>
      <origin rpy="0 0 0" xyz="0.00606 0.0 0.01903"/>
      <mass value="0.21905"/>
      <inertia ixx="0.00010664534" ixy="5.383e-08" ixz="4.91832e-06" iyy="0.00015585103" iyz="1.7942e-07" izz="0.00021982177"/>
    </inertial>
  </link>
  <joint name="base_hbc_receiver" type="fixed">
    <parent link="base"/>
    <child link="hbc_receiver"/>
    <origin rpy="0 0 0" xyz="-0.04350 0.0 0.14400"/>
  </joint>
  <link name="hbc_receiver">
    <inertial>
      <origin rpy="0 0 0" xyz="-0.00144 -0.00075 -0.01143"/>
      <mass value="0.60727"/>
      <inertia ixx="0.00172041475" ixy="2.466045e-05" ixz="1.95244e-06" iyy="0.00100683572" iyz="3.598867e-05" izz="0.00217149159"/>
    </inertial>
  </link>
  <link name="imu_link"/>
  <joint name="imu_joint" type="fixed">
    <parent link="base"/>
    <child link="imu_link"/>
    <origin rpy="3.141592653589793 0.0 3.141592653589793" xyz="-0.25565 0.00255 0.07672"/>
  </joint>
  <joint name="base_to_depth_camera_left_camera" type="fixed">
    <parent link="base"/>
    <child link="depth_camera_left_camera"/>
    <origin rpy="0.0 0.7330382858376184 1.5707963267948966" xyz="-0.02500 0.09230 0.01230"/>
  </joint>
  <link name="depth_camera_left_camera">
    <inertial>
      <origin rpy="0 0 0" xyz="-0.01352 -0.02667 -0.00198"/>
      <mass value="0.11196"/>
      <inertia ixx="0.00011356938" ixy="3.5285e-06" ixz="4.9332e-07" iyy="2.382311e-05" iyz="3.3737e-07" izz="0.00012178739"/>
    </inertial>
  </link>
  <joint name="depth_camera_left_camera_to_camera_parent" type="fixed">
    <parent link="depth_camera_left_camera"/>
    <child link="depth_camera_left_camera_parent"/>
    <origin rpy="0.0 0.0 0.0" xyz="0.0 0.0 0.0"/>
  </joint>
  <link name="depth_camera_left_camera_parent"/>
  <joint name="depth_camera_left_camera_parent_to_depth_frame" type="fixed">
    <parent link="depth_camera_left_camera_parent"/>
    <child link="depth_camera_left_depth_frame"/>
    <origin rpy="0.0 0.0 0.0" xyz="0.0 0.0 0.0"/>
  </joint>
  <link name="depth_camera_left_depth_frame"/>
  <joint name="depth_camera_left_camera_depth_to_depth_optical_frame" type="fixed">
    <parent link="depth_camera_left_depth_frame"/>
    <child link="depth_camera_left_depth_optical_frame"/>
    <origin rpy="-1.5707963267948966 0.0 -1.5707963267948966" xyz="0.0 0.0 0.0"/>
  </joint>
  <link name="depth_camera_left_depth_optical_frame"/>
  <joint name="base_to_depth_camera_right_camera" type="fixed">
    <parent link="base"/>
    <child link="depth_camera_right_camera"/>
    <origin rpy="0.0 0.7330382858376184 -1.5707963267948966" xyz="0.02500 -0.09230 0.01230"/>
  </joint>
  <link name="depth_camera_right_camera">
    <inertial>
      <origin rpy="0 0 0" xyz="-0.01352 -0.02667 -0.00198"/>
      <mass value="0.11196"/>
      <inertia ixx="0.00011356938" ixy="3.5285e-06" ixz="4.9332e-07" iyy="2.382311e-05" iyz="3.3737e-07" izz="0.00012178739"/>
    </inertial>
  </link>
  <joint name="depth_camera_right_camera_to_camera_parent" type="fixed">
    <parent link="depth_camera_right_camera"/>
    <child link="depth_camera_right_camera_parent"/>
    <origin rpy="0.0 0.0 0.0" xyz="0.0 0.0 0.0"/>
  </joint>
  <link name="depth_camera_right_camera_parent"/>
  <joint name="depth_camera_right_camera_parent_to_depth_frame" type="fixed">
    <parent link="depth_camera_right_camera_parent"/>
    <child link="depth_camera_right_depth_frame"/>
    <origin rpy="0.0 0.0 0.0" xyz="0.0 0.0 0.0"/>
  </joint>
  <link name="depth_camera_right_depth_frame"/>
  <joint name="depth_camera_right_camera_depth_to_depth_optical_frame" type="fixed">
    <parent link="depth_camera_right_depth_frame"/>
    <child link="depth_camera_right_depth_optical_frame"/>
    <origin rpy="-1.5707963267948966 0.0 -1.5707963267948966" xyz="0.0 0.0 0.0"/>
  </joint>
  <link name="depth_camera_right_depth_optical_frame"/>
  <joint name="base_to_lidar_parent" type="fixed">
    <parent link="base"/>
    <child link="lidar_parent"/>
    <origin rpy="0 0 1.5707963267948966" xyz="-0.310 0.0 0.1585"/>
  </joint>
  <joint name="lidar_parent_to_lidar" type="fixed">
    <parent link="lidar_parent"/>
    <child link="lidar"/>
    <origin rpy="0 0 1.5707963267948966" xyz="0 0 0"/>
  </joint>
  <link name="lidar_parent"/>
  <link name="lidar">
    <visual>
      <origin xyz="0 0 0"/>
      <!-- <geometry>
        <mesh filename="package://ocs2_robotic_assets/resources/anymal_d/meshes/lidar.dae"/>
      </geometry> -->
      <geometry>
        <sphere radius="0.022" />
      </geometry>
    </visual>
    <visual>
      <origin xyz="0 0 0"/>
      <!-- <geometry>
        <mesh filename="package://ocs2_robotic_assets/resources/anymal_d/meshes/lidar_guard.dae"/>
      </geometry> -->
      <geometry>
        <sphere radius="0.022" />
      </geometry>
    </visual>
    <collision>
      <origin rpy="0 0 0" xyz="0 0 0"/>
      <geometry>
        <cylinder length="0.1355" radius="0.07"/>
      </geometry>
    </collision>
    <inertial>
      <origin rpy="0.0 0.0 0.0" xyz="-0.00371 -0.00326 -0.00485"/>
      <mass value="0.9017"/>
      <inertia ixx="0.00111563406" ixy="0.00012074344" ixz="0.00011445184" iyy="0.00114682455" iyz="0.00010431906" izz="0.00132807373"/>
    </inertial>
  </link>
  <link
    name="LF_hip">
    <inertial>
      <origin
        xyz="-0.0054 0.00194 -0.000105"
        rpy="0 0 0" />
      <mass
        value="0.678" />
      <inertia
        ixx="0.00048"
        ixy="-3.01E-06"
        ixz="1.11E-06"
        iyy="0.000884"
        iyz="-1.42E-06"
        izz="0.000596" />
    </inertial>
    <visual>
      <origin
        xyz="0 0 0"
        rpy="3.1415 0 0" />
      <geometry>
        <mesh
          filename="package://ocs2_robotic_assets/resources/go2/dae/hip.dae" />
      </geometry>
      <material
        name="">
        <color
          rgba="1 1 1 1" />
      </material>
    </visual>
    <collision>
      <origin rpy="1.5707963267948966 0 0" xyz="0 -0.08 0" />
      <geometry>
        <cylinder length="0.04" radius="0.046" />
      </geometry>
    </collision>
  </link>
  <joint
    name="LF_HAA"
    type="revolute">
    <origin
      xyz="0.1934 0.0465 0"
      rpy="0 0 0" />
    <parent
      link="base" />
    <child
      link="LF_hip" />
    <axis
      xyz="1 0 0" />
    <limit
      lower="-1.0472"
      upper="1.0472"
      effort="23.7"
      velocity="30.1" />
  </joint>
  <link
    name="LF_thigh">
    <inertial>
      <origin
        xyz="-0.00374 -0.0223 -0.0327"
        rpy="0 0 0" />
      <mass
        value="1.152" />
      <inertia
        ixx="0.00584"
        ixy="8.72E-05"
        ixz="-0.000289"
        iyy="0.0058"
        iyz="0.000808"
        izz="0.00103" />
    </inertial>
    <visual>
      <origin
        xyz="0 0 0"
        rpy="0 0 0" />
      <geometry>
        <mesh
          filename="package://ocs2_robotic_assets/resources/go2/dae/thigh.dae" />
      </geometry>
      <material
        name="">
        <color
          rgba="1 1 1 1" />
      </material>
    </visual>
    <collision>
      <origin rpy="0 1.5707963267948966 0" xyz="0 0 -0.1065" />
      <geometry>
        <box size="0.213 0.0245 0.034" />
      </geometry>
    </collision>
  </link>
  <joint
    name="LF_HFE"
    type="revolute">
    <origin
      xyz="0 0.0955 0"
      rpy="0 0 0" />
    <parent
      link="LF_hip" />
    <child
      link="LF_thigh" />
    <axis
      xyz="0 1 0" />
    <limit
      lower="-1.5708"
      upper="3.4907"
      effort="23.7"
      velocity="30.1" />
  </joint>
  <link
    name="LF_shank">
    <inertial>
      <origin
        xyz="0.00548 -0.000975 -0.115"
        rpy="0 0 0" />
      <mass
        value="0.154" />
      <inertia
        ixx="0.00108"
        ixy="3.4E-07"
        ixz="1.72E-05"
        iyy="0.0011"
        iyz="8.28E-06"
        izz="3.29E-05" />
    </inertial>
    <visual>
      <origin
        xyz="0 0 0"
        rpy="0 0 0" />
      <geometry>
        <mesh
          filename="package://ocs2_robotic_assets/resources/go2/dae/calf.dae" />
      </geometry>
      <material
        name="">
        <color
          rgba="1 1 1 1" />
      </material>
    </visual>
    <collision>
      <origin rpy="0 -0.21 0" xyz="0.008 0 -0.06" />
      <geometry>
        <cylinder length="0.12" radius="0.012" />
      </geometry>
    </collision>
  </link>
  <joint
    name="LF_KFE"
    type="revolute">
    <origin
      xyz="0 0 -0.213"
      rpy="0 0 0" />
    <parent
      link="LF_thigh" />
    <child
      link="LF_shank" />
    <axis
      xyz="0 1 0" />
    <limit
      lower="-2.7227"
      upper="-0.83776"
      effort="45.43"
      velocity="15.70" />
  </joint>
  <link
    name="FL_calflower">
    <collision>
      <origin rpy="0 0 0" xyz="0 0 0" />
      <geometry>
        <cylinder length="0.065" radius="0.011" />
      </geometry>
    </collision>
  </link>
  <joint
    name="FL_calflower_joint"
    type="fixed">
    <origin
      xyz="0.020 0 -0.148"
      rpy="0 0.05 0" />
    <parent
      link="LF_shank" />
    <child
      link="FL_calflower" />
    <axis
      xyz="0 0 0" />
  </joint>
  <link
    name="FL_calflower1">
    <collision>
      <origin rpy="0 0 0" xyz="0 0 0" />
      <geometry>
        <cylinder length="0.03" radius="0.0155" />
      </geometry>
    </collision>
  </link>
  <joint
    name="FL_calflower1_joint"
    type="fixed">
    <origin
      xyz="-0.01 0 -0.04"
      rpy="0 0.48 0" />
    <parent
      link="FL_calflower" />
    <child
      link="FL_calflower1" />
    <axis
      xyz="0 0 0" />
  </joint>
  <link
    name="LF_FOOT">
    <inertial>
      <origin
        xyz="0 0 0"
        rpy="0 0 0" />
      <mass
        value="0.04" />
      <inertia
        ixx="9.6e-06"
        ixy="0"
        ixz="0"
        iyy="9.6e-06"
        iyz="0"
        izz="9.6e-06" />
    </inertial>
    <visual>
      <origin
        xyz="0 0 0"
        rpy="0 0 0" />
      <geometry>
        <mesh
          filename="package://ocs2_robotic_assets/resources/go2/dae/foot.dae" />
      </geometry>
      <material
        name="">
        <color
          rgba="1 1 1 1" />
      </material>
    </visual>
    <collision>
      <origin rpy="0 0 0" xyz="-0.002 0 0" />
      <geometry>
        <sphere radius="0.022" />
      </geometry>
    </collision>
  </link>
  <joint
    name="FL_foot_joint"
    type="fixed" dont_collapse="true">
    <origin
      xyz="0 0 -0.213"
      rpy="0 0 0" />
    <parent
      link="LF_shank" />
    <child
      link="LF_FOOT" />
    <axis
      xyz="0 0 0" />
  </joint>
  <link
    name="RF_hip">
        <inertial>
      <origin
        xyz="-0.0054 -0.00194 -0.000105"
        rpy="0 0 0" />
      <mass
        value="0.678" />
      <inertia
        ixx="0.00048"
        ixy="3.01E-06"
        ixz="1.11E-06"
        iyy="0.000884"
        iyz="1.42E-06"
        izz="0.000596" />
    </inertial>
    <visual>
      <origin
        xyz="0 0 0"
        rpy="3.1415 0 0" />
      <geometry>
        <mesh
          filename="package://ocs2_robotic_assets/resources/go2/dae/hip.dae" />
      </geometry>
      <material
        name="">
        <color
          rgba="1 1 1 1" />
      </material>
    </visual>
    <collision>
      <origin rpy="1.5707963267948966 0 0" xyz="0 -0.08 0" />
      <geometry>
        <cylinder length="0.04" radius="0.046" />
      </geometry>
    </collision>
  </link>
  <joint
    name="RF_HAA"
    type="revolute">
    <origin
      xyz="0.1934 -0.0465 0"
      rpy="0 0 0" />
    <parent
      link="base" />
    <child
      link="RF_hip" />
    <axis
      xyz="1 0 0" />
    <limit
      lower="-1.0472"
      upper="1.0472"
      effort="23.7"
      velocity="30.1" />
  </joint>
  <link
    name="RF_thigh">
    <inertial>
      <origin
        xyz="-0.00374 0.0223 -0.0327"
        rpy="0 0 0" />
      <mass
        value="1.152" />
      <inertia
        ixx="0.00584"
        ixy="8.72E-05"
        ixz="-0.000289"
        iyy="0.0058"
        iyz="0.000808"
        izz="0.00103" />
    </inertial>
    <visual>
      <origin
        xyz="0 0 0"
        rpy="0 0 0" />
      <geometry>
        <mesh
          filename="package://ocs2_robotic_assets/resources/go2/dae/thigh.dae" />
      </geometry>
      <material
        name="">
        <color
          rgba="1 1 1 1" />
      </material>
    </visual>
    <collision>
      <origin rpy="0 1.5707963267948966 0" xyz="0 0 -0.1065" />
      <geometry>
        <box size="0.213 0.0245 0.034" />
      </geometry>
    </collision>
  </link>
  <joint
    name="RF_HFE"
    type="revolute">
    <origin
      xyz="0 -0.0955 0"
      rpy="0 0 0" />
    <parent
      link="RF_hip" />
    <child
      link="RF_thigh" />
    <axis
      xyz="0 1 0" />
    <limit
      lower="-1.5708"
      upper="3.4907"
      effort="23.7"
      velocity="30.1" />
  </joint>
  <link
    name="RF_shank">
    <inertial>
      <origin
        xyz="0.00548 0.000975 -0.115"
        rpy="0 0 0" />
      <mass
        value="0.154" />
      <inertia
        ixx="0.00108"
        ixy="-3.4E-07"
        ixz="1.72E-05"
        iyy="0.0011"
        iyz="-8.28E-06"
        izz="3.29E-05" />
    </inertial>
    <visual>
      <origin
        xyz="0 0 0"
        rpy="0 0 0" />
      <geometry>
        <mesh
          filename="package://ocs2_robotic_assets/resources/go2/dae/calf.dae" />
      </geometry>
      <material
        name="">
        <color
          rgba="1 1 1 1" />
      </material>
    </visual>
    <collision>
      <origin rpy="0 -0.2 0" xyz="0.01 0 -0.06" />
      <geometry>
        <cylinder length="0.12" radius="0.013" />
      </geometry>
    </collision>
  </link>
  <joint
    name="RF_KFE"
    type="revolute">
    <origin
      xyz="0 0 -0.213"
      rpy="0 0 0" />
    <parent
      link="RF_thigh" />
    <child
      link="RF_shank" />
    <axis
      xyz="0 1 0" />
    <limit
      lower="-2.7227"
      upper="-0.83776"
      effort="45.43"
      velocity="15.70" />
  </joint>
  <link
    name="FR_calflower">
    <collision>
      <origin rpy="0 0 0" xyz="0 0 0" />
      <geometry>
        <cylinder length="0.065" radius="0.011" />
      </geometry>
    </collision>
  </link>
  <joint
    name="FR_calflower_joint"
    type="fixed">
    <origin
      xyz="0.020 0 -0.148"
      rpy="0 0.05 0" />
    <parent
      link="RF_shank" />
    <child
      link="FR_calflower" />
    <axis
      xyz="0 0 0" />
  </joint>
  <link
    name="FR_calflower1">
    <collision>
      <origin rpy="0 0 0" xyz="0 0 0" />
      <geometry>
        <cylinder length="0.03" radius="0.0155" />
      </geometry>
    </collision>
  </link>
  <joint
    name="FR_calflower1_joint"
    type="fixed">
    <origin
      xyz="-0.01 0 -0.04"
      rpy="0 0.48 0" />
    <parent
      link="FR_calflower" />
    <child
      link="FR_calflower1" />
    <axis
      xyz="0 0 0" />
  </joint>
  <link
    name="RF_FOOT">
    <inertial>
      <origin
        xyz="0 0 0"
        rpy="0 0 0" />
      <mass
        value="0.04" />
      <inertia
        ixx="9.6e-06"
        ixy="0"
        ixz="0"
        iyy="9.6e-06"
        iyz="0"
        izz="9.6e-06" />
    </inertial>
    <visual>
      <origin
        xyz="0 0 0"
        rpy="0 0 0" />
      <geometry>
        <mesh
          filename="package://ocs2_robotic_assets/resources/go2/dae/foot.dae" />
      </geometry>
      <material
        name="">
        <color
          rgba="1 1 1 1" />
      </material>
    </visual>
    <collision>
      <origin rpy="0 0 0" xyz="-0.002 0 0" />
      <geometry>
        <sphere radius="0.022" />
      </geometry>
    </collision>
  </link>
  <joint
    name="FR_foot_joint"
    type="fixed" dont_collapse="true">
    <origin
      xyz="0 0 -0.213"
      rpy="0 0 0" />
    <parent
      link="RF_shank" />
    <child
      link="RF_FOOT" />
    <axis
      xyz="0 0 0" />
  </joint>  
  <link
    name="LH_hip">
    <inertial>
      <origin
        xyz="0.0054 0.00194 -0.000105"
        rpy="0 0 0" />
      <mass
        value="0.678" />
      <inertia
        ixx="0.00048"
        ixy="3.01E-06"
        ixz="-1.11E-06"
        iyy="0.000884"
        iyz="-1.42E-06"
        izz="0.000596" />
    </inertial>
    <visual>
      <origin
        xyz="0 0 0"
        rpy="0 3.1415 0" />
      <geometry>
        <mesh
          filename="package://ocs2_robotic_assets/resources/go2/dae/hip.dae" />
      </geometry>
      <material
        name="">
        <color
          rgba="1 1 1 1" />
      </material>
    </visual>
    <collision>
      <origin rpy="1.5707963267948966 0 0" xyz="0 0.08 0" />
      <geometry>
        <cylinder length="0.04" radius="0.046" />
      </geometry>
    </collision>
  </link>
  <joint
    name="LH_HAA"
    type="revolute">
    <origin
      xyz="-0.1934 0.0465 0"
      rpy="0 0 0" />
    <parent
      link="base" />
    <child
      link="LH_hip" />
    <axis
      xyz="1 0 0" />
    <limit
      lower="-1.0472"
      upper="1.0472"
      effort="23.7"
      velocity="30.1" />
  </joint>
  <link
    name="LH_thigh">
    <inertial>
      <origin
        xyz="-0.00374 -0.0223 -0.0327"
        rpy="0 0 0" />
      <mass
        value="1.152" />
      <inertia
        ixx="0.00584"
        ixy="8.72E-05"
        ixz="-0.000289"
        iyy="0.0058"
        iyz="0.000808"
        izz="0.00103" />
    </inertial>
    <visual>
      <origin
        xyz="0 0 0"
        rpy="0 0 0" />
      <geometry>
        <mesh
          filename="package://ocs2_robotic_assets/resources/go2/dae/thigh.dae" />
      </geometry>
      <material
        name="">
        <color
          rgba="1 1 1 1" />
      </material>
    </visual>
    <collision>
      <origin rpy="0 1.5707963267948966 0" xyz="0 0 -0.1065" />
      <geometry>
        <box size="0.213 0.0245 0.034" />
      </geometry>
    </collision>
  </link>
  <joint
    name="LH_HFE"
    type="revolute">
    <origin
      xyz="0 0.0955 0"
      rpy="0 0 0" />
    <parent
      link="LH_hip" />
    <child
      link="LH_thigh" />
    <axis
      xyz="0 1 0" />
    <limit
      lower="-0.5236"
      upper="4.5379"
      effort="23.7"
      velocity="30.1" />
  </joint>
  <link
    name="LH_shank">
    <inertial>
      <origin
        xyz="0.00548 -0.000975 -0.115"
        rpy="0 0 0" />
      <mass
        value="0.154" />
      <inertia
        ixx="0.00108"
        ixy="3.4E-07"
        ixz="1.72E-05"
        iyy="0.0011"
        iyz="8.28E-06"
        izz="3.29E-05" />
    </inertial>
    <visual>
      <origin
        xyz="0 0 0"
        rpy="0 0 0" />
      <geometry>
        <mesh
          filename="package://ocs2_robotic_assets/resources/go2/dae/calf.dae" />
      </geometry>
      <material
        name="">
        <color
          rgba="1 1 1 1" />
      </material>
    </visual>
    <collision>
      <origin rpy="0 -0.2 0" xyz="0.01 0 -0.06" />
      <geometry>
        <cylinder length="0.12" radius="0.013" />
      </geometry>
    </collision>
  </link>
  <joint
    name="LH_KFE"
    type="revolute">
    <origin
      xyz="0 0 -0.213"
      rpy="0 0 0" />
    <parent
      link="LH_thigh" />
    <child
      link="LH_shank" />
    <axis
      xyz="0 1 0" />
    <limit
      lower="-2.7227"
      upper="-0.83776"
      effort="45.43"
      velocity="15.70" />
  </joint>
  <link
    name="RL_calflower">
    <collision>
      <origin rpy="0 0 0" xyz="0 0 0" />
      <geometry>
        <cylinder length="0.065" radius="0.011" />
      </geometry>
    </collision>
  </link>
  <joint
    name="RL_calflower_joint"
    type="fixed">
    <origin
      xyz="0.020 0 -0.148"
      rpy="0 0.05 0" />
    <parent
      link="LH_shank" />
    <child
      link="RL_calflower" />
    <axis
      xyz="0 0 0" />
  </joint>
  <link
    name="RL_calflower1">
    <collision>
      <origin rpy="0 0 0" xyz="0 0 0" />
      <geometry>
        <cylinder length="0.03" radius="0.0155" />
      </geometry>
    </collision>
  </link>
  <joint
    name="RL_calflower1_joint"
    type="fixed">
    <origin
      xyz="-0.01 0 -0.04"
      rpy="0 0.48 0" />
    <parent
      link="RL_calflower" />
    <child
      link="RL_calflower1" />
    <axis
      xyz="0 0 0" />
  </joint>
  <link
    name="LH_FOOT">
    <inertial>
      <origin
        xyz="0 0 0"
        rpy="0 0 0" />
      <mass
        value="0.04" />
      <inertia
        ixx="9.6e-06"
        ixy="0"
        ixz="0"
        iyy="9.6e-06"
        iyz="0"
        izz="9.6e-06" />
    </inertial>
    <visual>
      <origin
        xyz="0 0 0"
        rpy="0 0 0" />
      <geometry>
        <mesh
          filename="package://ocs2_robotic_assets/resources/go2/dae/foot.dae" />
      </geometry>
      <material
        name="">
        <color
          rgba="1 1 1 1" />
      </material>
    </visual>
    <collision>
      <origin rpy="0 0 0" xyz="-0.002 0 0" />
      <geometry>
        <sphere radius="0.022" />
      </geometry>
    </collision>
  </link>
  <joint
    name="RL_foot_joint"
    type="fixed" dont_collapse="true">
    <origin
      xyz="0 0 -0.213"
      rpy="0 0 0" />
    <parent
      link="LH_shank" />
    <child
      link="LH_FOOT" />
    <axis
      xyz="0 0 0" />
  </joint>  
  <link
    name="RH_hip">
    <inertial>
      <origin
        xyz="0.0054 -0.00194 -0.000105"
        rpy="0 0 0" />
      <mass
        value="0.678" />
      <inertia
        ixx="0.00048"
        ixy="-3.01E-06"
        ixz="-1.11E-06"
        iyy="0.000884"
        iyz="1.42E-06"
        izz="0.000596" />
    </inertial>
    <visual>
      <origin
        xyz="0 0 0"
        rpy="3.1415 3.1415 0" />
      <geometry>
        <mesh
          filename="package://ocs2_robotic_assets/resources/go2/dae/hip.dae" />
      </geometry>
      <material
        name="">
        <color
          rgba="1 1 1 1" />
      </material>
    </visual>
    <collision>
      <origin rpy="1.5707963267948966 0 0" xyz="0 -0.08 0" />
      <geometry>
        <cylinder length="0.04" radius="0.046" />
      </geometry>
    </collision>
  </link>
  <joint
    name="RH_HAA"
    type="revolute">
    <origin
      xyz="-0.1934 -0.0465 0"
      rpy="0 0 0" />
    <parent
      link="base" />
    <child
      link="RH_hip" />
    <axis
      xyz="1 0 0" />
    <limit
      lower="-1.0472"
      upper="1.0472"
      effort="23.7"
      velocity="30.1" />
  </joint>
  <link
    name="RH_thigh">
    <inertial>
      <origin
        xyz="-0.00374 0.0223 -0.0327"
        rpy="0 0 0" />
      <mass
        value="1.152" />
      <inertia
        ixx="0.00584"
        ixy="-8.72E-05"
        ixz="-0.000289"
        iyy="0.0058"
        iyz="-0.000808"
        izz="0.00103" />
    </inertial>
    <visual>
      <origin
        xyz="0 0 0"
        rpy="0 0 0" />
      <geometry>
        <mesh
          filename="package://ocs2_robotic_assets/resources/go2/dae/thigh.dae" />
      </geometry>
      <material
        name="">
        <color
          rgba="1 1 1 1" />
      </material>
    </visual>
    <collision>
      <origin rpy="0 1.5707963267948966 0" xyz="0 0 -0.1065" />
      <geometry>
        <box size="0.213 0.0245 0.034" />
      </geometry>
    </collision>
  </link>
  <joint
    name="RH_HFE"
    type="revolute">
    <origin
      xyz="0 -0.0955 0"
      rpy="0 0 0" />
    <parent
      link="RH_hip" />
    <child
      link="RH_thigh" />
    <axis
      xyz="0 1 0" />
    <limit
      lower="-0.5236"
      upper="4.5379"
      effort="23.7"
      velocity="30.1" />
  </joint>
  <link
    name="RH_shank">
    <inertial>
      <origin
        xyz="0.00548 0.000975 -0.115"
        rpy="0 0 0" />
      <mass
        value="0.154" />
      <inertia
        ixx="0.00108"
        ixy="-3.4E-07"
        ixz="1.72E-05"
        iyy="0.0011"
        iyz="-8.28E-06"
        izz="3.29E-05" />
    </inertial>
    <visual>
      <origin
        xyz="0 0 0"
        rpy="0 0 0" />
      <geometry>
        <mesh
          filename="package://ocs2_robotic_assets/resources/go2/dae/calf.dae" />
      </geometry>
      <material
        name="">
        <color
          rgba="1 1 1 1" />
      </material>
    </visual>
    <collision>
      <origin rpy="0 -0.2 0" xyz="0.01 0 -0.06" />
      <geometry>
        <cylinder length="0.12" radius="0.013" />
      </geometry>
    </collision>
  </link>
  <joint
    name="RH_KFE"
    type="revolute">
    <origin
      xyz="0 0 -0.213"
      rpy="0 0 0" />
    <parent
      link="RH_thigh" />
    <child
      link="RH_shank" />
    <axis
      xyz="0 1 0" />
    <limit
      lower="-2.7227"
      upper="-0.83776"
      effort="45.43"
      velocity="15.70" />
  </joint>
  <link
    name="RR_calflower">
    <collision>
      <origin rpy="0 0 0" xyz="0 0 0" />
      <geometry>
        <cylinder length="0.065" radius="0.011" />
      </geometry>
    </collision>
  </link>
  <joint
    name="RR_calflower_joint"
    type="fixed">
    <origin
      xyz="0.020 0 -0.148"
      rpy="0 0.05 0" />
    <parent
      link="RH_shank" />
    <child
      link="RR_calflower" />
    <axis
      xyz="0 0 0" />
  </joint>
  <link
    name="RR_calflower1">
    <collision>
      <origin rpy="0 0 0" xyz="0 0 0" />
      <geometry>
        <cylinder length="0.03" radius="0.0155" />
      </geometry>
    </collision>
  </link>
  <joint
    name="RR_calflower1_joint"
    type="fixed">
    <origin
      xyz="-0.01 0 -0.04"
      rpy="0 0.48 0" />
    <parent
      link="RR_calflower" />
    <child
      link="RR_calflower1" />
    <axis
      xyz="0 0 0" />
  </joint>
  <link
    name="RH_FOOT">
    <inertial>
      <origin
        xyz="0 0 0"
        rpy="0 0 0" />
      <mass
        value="0.04" />
      <inertia
        ixx="9.6e-06"
        ixy="0"
        ixz="0"
        iyy="9.6e-06"
        iyz="0"
        izz="9.6e-06" />
    </inertial>
    <visual>
      <origin
        xyz="0 0 0"
        rpy="0 0 0" />
      <geometry>
        <mesh
          filename="package://ocs2_robotic_assets/resources/go2/dae/foot.dae" />
      </geometry>
      <material
        name="">
        <color
          rgba="1 1 1 1" />
      </material>
    </visual>
    <collision>
      <origin rpy="0 0 0" xyz="-0.002 0 0" />
      <geometry>
        <sphere radius="0.022" />
      </geometry>
    </collision>
  </link>
  <joint
    name="RR_foot_joint"
    type="fixed" dont_collapse="true">
    <origin
      xyz="0 0 -0.213"
      rpy="0 0 0" />
    <parent
      link="RH_shank" />
    <child
      link="RH_FOOT" />
    <axis
      xyz="0 0 0" />
  </joint>  
</robot>
